Workbook

Sheet University Channel Data
B1: channel_name | C1: subscribers | D1: views | E1: total_videos | F1: playlist_id
A2: 0 | B2: CityUHongKong | C2: 3200 | D2: 4201343 | E2: 412 | F2: UU1OVYBbIxEFAzm_Hc4nvG9w
A3: 1 | B3: The Hong Kong Polytechnic University | C3: 7430 | D3: 3307005 | E3: 655 | F3: UUkio4asleKcQVRVEM8RnXlQ
A4: 2 | B4: The University of Hong Kong | C4: 11400 | D4: 2303723 | E4: 692 | F4: UUvZ4seZaqaO_A_WPfL-d9WQ
A5: 3 | B5: HKUST | C5: 4450 | D5: 707562 | E5: 414 | F5: UUdRnXk2yE-4olVkgz0tECvw
A6: 4 | B6: CUHK Channel | C6: 12300 | D6: 2130683 | E6: 531 | F6: UUeG0cjZClabYTnYZldpCNwQ

Sheet YouTube University Data_Fin (2)
A1: ID | B1: Channel_name | C1: Title | D1: Title_language | E1: Description | F1: Category | G1: Published_date | H1: Duration | I1: Tags | J1: Views | K1: Likes | L1: Favourites | M1: Comments | N1: Month | O1: Year | P1: Category_name
A2: 0 | B2: HKUST | C2: HKUST Named Professorships | Wu Chien-Shiung Professor of Science Prof. Jiannong WANG | D2: =VLOOKUP(YouTube_University_Data_Final[[#This Row],[Title]],[1]!YouTube_University_Data_Final[[Title]:[Title_language]],2,FALSE) -> English | E2: [ #HKUST Named Professorships | Wu Chien-Shiung Professor of Science Prof. Jiannong WANG ] For three decades, research conducted by Prof. Jiannong WANG, Head and Chair Professor of #HKUST's Department of Physics, had shed light on the fundamental properties of materials and how they make modern life possible. Prof. Wang has achieved international recognition for her state-of-the-art research on the physical properties of materials. She perfectly exemplifies the mission of HKUST’s Department of Physics: to nurture “a sense of wonder about the natural world” through innovation and knowledge advancement. Her research interests cover Condensed Matter Physics, Material Physics, Semiconductor Quantum Structures, Semiconductor Spintronics, and Nanostructured Materials. Wu Chien-Shiung Professorship was established by an anonymous donor and is named after the Chinese physicist Prof. Chien-Shiung Wu, who was awarded the first Wolf Prize in Physics in 1978 for a revolutionary discovery in the field of atomic and nuclear physics. Named Professorships Program - Partnership for Excellence To know more, please visit：https://np.hkust.edu.hk/en/top_minds_details.php?id=69 #HKUSTfaculty #HKUSTresearch #HKUSTnamedprofessors #NamedProfessorship #Research #Materials #Innovation | F2: 27 | G2: 44838 | H2: 147 | I2: ['HKUST'] | J2: 35 | K2: 1 | L2: 0 | M2: 0 | N2: Oct | O2: 2022 | P2: Education
A3: 1 | B3: HKUST | C3: HKUST Named Professorships | Dr William M W Mong Professor of Nanoscience Prof. Xi DAI | D3: =VLOOKUP(YouTube_University_Data_Final[[#This Row],[Title]],[1]!YouTube_University_Data_Final[[Title]:[Title_language]],2,FALSE) -> English | E3: [ #HKUST Named Professorships | Dr William M W Mong Professor of Nanoscience Prof. Xi DAI ] The exceptional properties of #Quantum materials may represent the future of computers and consumer electronics. A leading expert in the theory of quantum materials, #HKUST’s Prof. Xi DAI is spearheading research efforts at the frontiers of material sciences. Prof. Dai’s research on topological materials is instrumental in bridging the gap between theoretical physics and experimental sciences. He and his team take abstract theoretical ideas about topological matter and realize them in real-world materials—ultimately helping scientists to create a new “periodic table” of materials Prof. Dai’s research interests cover Strongly Correlated Materials, Computational Materials Science, Quantum Materials, Topological Matters, and Unconventional Superconductors. Dr. William M W Mong Professorship in Nanoscience is contributed by Shun Hing Education and Charity Fund. "We believe that the transformation of society relies on technological advancement. We hope our donation to The Hong Kong University of Science and Technology will not only enhance its search for excellence in nanoscience and nanotechnology, but also expand Hong Kong's horizons in scientific discovery beyond the local community" said by Mr. David Mong. Named Professorships Program - Partnership for Excellence To know more, please visit：https://np.hkust.edu.hk/en/top_minds_details.php?id=74 #HKUSTfaculty #HKUSTresearch #HKUSTnamedprofessors #NamedProfessorship #Research #QuantumMaterials #MaterialScience | F3: 27 | G3: 44837 | H3: 155 | I3: ['HKUST'] | J3: 70 | K3: 5 | L3: 0 | M3: 0 | N3: Oct | O3: 2022 | P3: Education
A4: 2 | B4: HKUST | C4: HKUST Named Professorships | IAS Paul C W Chu Professor Prof. Kam-Biu LUK | D4: =VLOOKUP(YouTube_University_Data_Final[[#This Row],[Title]],[1]!YouTube_University_Data_Final[[Title]:[Title_language]],2,FALSE) -> English | E4: [ #HKUST Named Professorships | IAS Paul C W Chu Professor Prof. Kam-Biu LUK ] “#Neutrinos are like magicians. They can change their identity right in front of us.” says Prof. Kam-Biu LUK, Chair Professor at #HKUST’s Department of Physics and HKUST Jockey Club Institute for Advanced Study (IAS). In 2012, Prof. Luk and his international colleagues announced their discovery of a new type of neutrino oscillation, observed deep underground in the Daya Bay Reactor Neutrino Experiment. As co-leader of this ground-breaking experiment, Prof. Luk received multiple prestigious awards. He joined HKUST and serves as Chair Professor of Physics in 2021. Prof. Luk’s research interests cover #ParticlePhysics, #Cosmology, Symmetries of Nature, Instrumentation, and Computational techniques. IAS Paul C W Chu Professorship is named after the University’s second President, Prof. Paul Ching-Wu Chu, who also served as the Founding Director of the HKUST Jockey Club Institute for Advanced Study (IAS). Named Professorships Program - Partnership for Excellence To know more, please visit： https://np.hkust.edu.hk/en/top_minds_details.php?id=72 #HKUSTfaculty #HKUSTresearch #HKUSTnamedprofessors #NamedProfessorship #Research #Physics | F4: 27 | G4: 44837 | H4: 144 | I4: ['HKUST'] | J4: 77 | K4: 5 | L4: 0 | M4: 0 | N4: Oct | O4: 2022 | P4: Education
A5: 3 | B5: HKUST | C5: Celebration of the 73rd Anniversary of the Founding of the People’s Republic of China | D5: =VLOOKUP(YouTube_University_Data_Final[[#This Row],[Title]],[1]!YouTube_University_Data_Final[[Title]:[Title_language]],2,FALSE) -> English | F5: 27 | G5: 44835 | H5: 1054 | I5: ['HKUST'] | J5: 697 | K5: 27 | L5: 0 | M5: 0 | N5: Oct | O5: 2022 | P5: Education
A6: 4 | B6: HKUST | C6: 阿尔兹海默症早期诊断及基因治疗研究 | D6: =VLOOKUP(YouTube_University_Data_Final[[#This Row],[Title]],[1]!YouTube_University_Data_Final[[Title]:[Title_language]],2,FALSE) -> Chinese | F6: 27 | G6: 44832 | H6: 91 | I6: ['HKUST'] | J6: 34 | K6: 1 | L6: 0 | M6: 1 | N6: Sep | O6: 2022 | P6: Education
A7: 5 | B7: HKUST | C7: Early Diagnosis and Gene Therapy for Alzheimer’s Disease | D7: =VLOOKUP(YouTube_University_Data_Final[[#This Row],[Title]],[1]!YouTube_University_Data_Final[[Title]:[Title_language]],2,FALSE) -> English | E7: Alzheimer's Disease (AD) may still be an irreversible condition that lacks effective treatments, but recent scientific breakthroughs are bringing great hope. Check out the promising advances made by researchers at #HKUST's Hong Kong Center for Neurodegenerative Diseases (HKCeND). #HKUSTresearch #AlzheimersDisease #Dementia #Aging #AgingResearch #Neuroscience #Research #ResearchBreakthrough | F7: 27 | G7: 44832 | H7: 91 | I7: ['HKUST'] | J7: 16 | K7: 1 | L7: 0 | M7: 1 | N7: Sep | O7: 2022 | P7: Education
A8: 6 | B8: HKUST | C8: 沉着破浪的无人船领航人 | D8: =VLOOKUP(YouTube_University_Data_Final[[#This Row],[Title]],[1]!YouTube_University_Data_Final[[Title]:[Title_language]],2,FALSE) -> Chinese | F8: 27 | G8: 44823 | H8: 60 | I8: ['HKUST'] | J8: 29 | K8: 1 | L8: 0 | M8: 0 | N8: Sep | O8: 2022 | P8: Education
A9: 7 | B9: HKUST | C9: Unmanned Vessels to Tackle #WaterPollution and Aid Rescue Missions | D9: =VLOOKUP(YouTube_University_Data_Final[[#This Row],[Title]],[1]!YouTube_University_Data_Final[[Title]:[Title_language]],2,FALSE) -> English | E9: What's the key to founding a #unicorn business? For #HKUST alumnus ZHANG Yunfei, Founder and President of world-leading unmanned ship corporation Zhuhai Yunzhou Intelligence Technology Ltd. (Yunzhou), it all started with a childhood passion for boats and an inventive spirit. Check out how the entrepreneurial journey of Yunfei and his team burgeoned at #HKUST and how their first-of-its-kind unmanned ships can help China tackle water pollution and perform dangerous water rescue missions. Learn more: https://bit.ly/3pqOrUQ #HKUSTinnovation #HKUSTentrepreneur #Innovation #Startup #Entrepreneur #WaterTreatment #WaterQuality #WaterRescue #Invention #Entrepreneurship | F9: 27 | G9: 44823 | H9: 2 | I9: ['HKUST'] | J9: 11 | K9: 0 | L9: 0 | M9: 0 | N9: Sep | O9: 2022 | P9: Education
A10: 8 | B10: HKUST | C10: 全球首款3D人造眼 | D10: =VLOOKUP(YouTube_University_Data_Final[[#This Row],[Title]],[1]!YouTube_University_Data_Final[[Title]:[Title_language]],2,FALSE) -> Chinese | F10: 27 | G10: 44818 | H10: 73 | I10: ['HKUST'] | J10: 47 | K10: 1 | L10: 0 | M10: 0 | N10: Sep | O10: 2022 | P10: Education
A11: 9 | B11: HKUST | C11: World's First 3D Artificial Eye | D11: =VLOOKUP(YouTube_University_Data_Final[[#This Row],[Title]],[1]!YouTube_University_Data_Final[[Title]:[Title_language]],2,FALSE) -> English | E11: How can we help visually impaired patients regain eyesight? Check out the world's first 3D artificial eye developed by #HKUST's research team and how it will bring new hope to visually impaired patients as well as enable humanoid robots to see. Learn more: https://bit.ly/3vnve9L #HKUSTresearch #HKUSTinnovation #HKUSTfaculty #ArtificialEye #BionicEye #Humanoid #Robotics #Innovation #Technology | F11: 27 | G11: 44818 | H11: 74 | I11: ['HKUST'] | J11: 59 | K11: 3 | L11: 0 | M11: 0 | N11: Sep | O11: 2022 | P11: Education
A12: 10 | B12: HKUST | C12: [ Inclusive and Energetic University Life | New Semester, New Beginning! ] | D12: =VLOOKUP(YouTube_University_Data_Final[[#This Row],[Title]],[1]!YouTube_University_Data_Final[[Title]:[Title_language]],2,FALSE) -> English | E12: How’s everyone settling into the new semester? Has it been a fun-filled two weeks? Let’s check out what plans these #HKUSTers have for their exciting year ahead. #HKUSTstudent #HKUSTpeople #HKUSTlife #University #UniversityLife #Campus #CampusLife #Freshmen #StreetInterview | F12: 27 | G12: 44818 | H12: 165 | I12: ['HKUST'] | J12: 39 | K12: 1 | L12: 0 | M12: 0 | N12: Sep | O12: 2022 | P12: Education
A13: 11 | B13: HKUST | C13: A Day in the Life of HKUST's Engineering Research Postgraduate Student Jungjin PARK | D13: =VLOOKUP(YouTube_University_Data_Final[[#This Row],[Title]],[1]!YouTube_University_Data_Final[[Title]:[Title_language]],2,FALSE) -> English | E13: HKUST Engineering Research Postgraduate Student Vlog - Jungjin PARK, MPhil Student of Mechanical and Aerospace Engineering The Hong Kong University of Science and Technology HKUST Engineering Research Postgraduate Study: https://seng.hkust.edu.hk/academics/r... Hong Kong PhD Fellowship Scheme - A Prestigious and Fully-Funded Option for Your PhD Studies: https://fytgs.hkust.edu.hk/scholarshi... @HKUST Engineering Research & RPG Studies #hkust #engineering#research #students #mphil #phd #vlog #adayinthelife #hkustengineering #hkpfs | F13: 27 | G13: 44818 | H13: 381 | I13: ['HKUST'] | J13: 209 | K13: 5 | L13: 0 | M13: 0 | N13: Sep | O13: 2022 | P13: Education
A14: 12 | B14: HKUST | C14: HKUST2.0 - Converging Creative Minds, Empowering a Better Future | D14: =VLOOKUP(YouTube_University_Data_Final[[#This Row],[Title]],[1]!YouTube_University_Data_Final[[Title]:[Title_language]],2,FALSE) -> English | E14: [ HKUST2.0 - Converging Creative Minds, Empowering a Better Future ] Since 1991, #HKUST has taken on a quest for excellence and innovation. Fast-forwarding to now, we are progressing from HKUST to a brand-new era of HKUST2.0 with HKUST(GZ). Check out how HKUST and HKUST(GZ) will jointly empower a better and more sustainable future for all. #HKUSTGZ #CrossCampus #Synergy #CrossDisciplinary #Education #HigherEducation #Univeristy #Research | F14: 27 | G14: 44813 | H14: 119 | I14: ['HKUST'] | J14: 124 | K14: 2 | L14: 0 | M14: 0 | N14: Sep | O14: 2022 | P14: Education
A15: 13 | B15: HKUST | C15: HKUST(GZ) Opening - Congratulatory Messages from Global Partners | D15: =VLOOKUP(YouTube_University_Data_Final[[#This Row],[Title]],[1]!YouTube_University_Data_Final[[Title]:[Title_language]],2,FALSE) -> English | F15: 27 | G15: 44812 | H15: 573 | I15: ['HKUST'] | J15: 190 | K15: 9 | L15: 0 | M15: 0 | N15: Sep | O15: 2022 | P15: Education
A16: 14 | B16: HKUST | C16: HKUST(GZ) Opening Torch Relay | D16: =VLOOKUP(YouTube_University_Data_Final[[#This Row],[Title]],[1]!YouTube_University_Data_Final[[Title]:[Title_language]],2,FALSE) -> English | E16: [ Spreading the #HKUST Spirit from Hong Kong to Guangzhou ] The #HKUST spirit knows no boundaries. Carrying our HKUST spirit from Hong Kong to Guangzhou, HKUST and HKUST(GZ) strives to make the world a better and more sustainable home for all. #HKUSTGZ #TorchRelay #Torch #Running #Relay #University #Sailing #Drone #Metaverse | F16: 27 | G16: 44812 | H16: 227 | I16: ['HKUST'] | J16: 306 | K16: 8 | L16: 0 | M16: 1 | N16: Sep | O16: 2022 | P16: Education
A17: 15 | B17: HKUST | C17: HKUST(GZ) Opening - HK & GZ Evening Celebrations Highlights | D17: =VLOOKUP(YouTube_University_Data_Final[[#This Row],[Title]],[1]!YouTube_University_Data_Final[[Title]:[Title_language]],2,FALSE) -> English | F17: 27 | G17: 44811 | H17: 145 | I17: ['HKUST'] | J17: 313 | K17: 6 | L17: 0 | M17: 0 | N17: Sep | O17: 2022 | P17: Education
A18: 16 | B18: HKUST | C18: HKUST(GZ) Opening - Evening Celebration in Hong Kong (Full Version) | D18: =VLOOKUP(YouTube_University_Data_Final[[#This Row],[Title]],[1]!YouTube_University_Data_Final[[Title]:[Title_language]],2,FALSE) -> English | F18: 27 | G18: 44810 | H18: 4760 | I18: ['HKUST'] | J18: 147 | K18: 2 | L18: 0 | M18: 0 | N18: Sep | O18: 2022 | P18: Education
A19: 17 | B19: HKUST | C19: HKUST(GZ) Opening - Guangzhou Celebration Highlights | D19: =VLOOKUP(YouTube_University_Data_Final[[#This Row],[Title]],[1]!YouTube_University_Data_Final[[Title]:[Title_language]],2,FALSE) -> English | E19: [ Share Our Joy for HKUST(GZ)'s Opening Celebration ] The opening of HKUST(GZ) marks a historic moment and turns a new chapter in HKUST's history. Check out some highlights of the celebrations in the Guangzhou campus and share our joy! #HKUSTevent #TorchRelay #PassTheTorch #NewBeginning #Celebration #Education #CrossCampus #HigherEducation #University #GBA #GreaterBayArea #Interdisciplinary #CrossDisciplinary #Metaverse | F19: 27 | G19: 44806 | H19: 139 | I19: ['HKUST'] | J19: 391 | K19: 6 | L19: 0 | M19: 0 | N19: Sep | O19: 2022 | P19: Education
A20: 18 | B20: HKUST | C20: HKUST(GZ) Opening - Congratulatory Messages | D20: =VLOOKUP(YouTube_University_Data_Final[[#This Row],[Title]],[1]!YouTube_University_Data_Final[[Title]:[Title_language]],2,FALSE) -> English | E20: [ Congratulatory Messages for HKUST(GZ)'s Opening ] #HKUST and HKUST(GZ) are so grateful to receive many good wishes from HKSAR government officials, our long-term friends and HKUST senior administrators for this exciting milestone of our journey. Our heartfelt thanks to: The Hon John Lee, GBM, SBS, PDSM, PMSM, Chief Executive of the HKSAR The Hon Chun-ying Leung, GBM, GBS, JP, Vice-Chairman of the National Committee of the Chinese People's Political Consultative Conference and Former Chief Executive of the HKSAR The Hon Mrs. Carrie Lam, GBM, GBS, JP, Former Chief Executive of the HKSAR Dr. Yuk-lin Choi, JP, Secretary for Education of the HKSAR Mr. Carlson Tong, GBS, JP, Chairman of the University Grants Committee Prof. Chia-wei Woo, GBS, CBE, Founding President of HKUST Dr. John Chan, GBS, JP, Founding Chairman of the Council and Chairman of the Court of HKUST Dr. Andrew Liao, GBM, GBS, SC, JP, Chairman of the Council of HKUST Prof. Wei Shyy, JP, President of HKUST Prof. Nancy Ip, SBS, MH, JP, President-Designate of HKUST Mr. Ian Fok, SBS, JP, Honorary Member of the Court of HKUST Dr. Vincent Lo, GBM, GBS, JP, Former Chairman of the Council and Honorary Chairman of the Court of HKUST Dr. Tung Chee-chen, The Tung Foundation #HKUSTevent #Congratulations #NewBeginning #Celebration #Education #CrossCampus #HigherEducation #University #GBA #GreaterBayArea #Interdisciplinary #CrossDisciplinary | F20: 27 | G20: 44806 | H20: 744 | I20: ['HKUST'] | J20: 208 | K20: 2 | L20: 0 | M20: 0 | N20: Sep | O20: 2022 | P20: Education
A21: 19 | B21: HKUST | C21: HKSUT(GZ) Opening Ceremony at Guangzhou | D21: =VLOOKUP(YouTube_University_Data_Final[[#This Row],[Title]],[1]!YouTube_University_Data_Final[[Title]:[Title_language]],2,FALSE) -> English | F21: 27 | G21: 44805 | H21: 1772 | I21: ['HKUST'] | J21: 267 | K21: 1 | L21: 0 | M21: 1 | N21: Sep | O21: 2022 | P21: Education
A22: 20 | B22: HKUST | C22: HKUST(GZ) Opening Ceremony - Event Highlights | D22: =VLOOKUP(YouTube_University_Data_Final[[#This Row],[Title]],[1]!YouTube_University_Data_Final[[Title]:[Title_language]],2,FALSE) -> English | E22: [ Celebrating the Beginning of HKUST2.0 with HKUST(GZ)'s Opening Today ] #HKUST is ecstatic to celebrate the opening of our new campus in Nansha, Guangzhou today! Under the unique “Unified HKUST, Complementary Campuses” framework, HKUST and HKUST(GZ) will jointly cultivate more future-oriented innovative talents and pioneer a new direction in higher education. Central Government, the Mainland and Hong Kong officials, Presidents and senior management of top universities around the world, business leaders, long-term partners and founding members of HKUST extended their greetings to HKUST(GZ) either in person or via the #metaverse at today's opening ceremony. Check out some highlights of this momentous day in the history of #HKUST: https://bit.ly/3KDccT7 Watch the ceremony held simultaneously at the state-of-the-art Guangzhou campus this morning: https://lnkd.in/gnBpiU6J #HKUSTevent #Education #CrossCampus #HigherEducation #University #GBA #GreaterBayArea #Interdisciplinary #CrossDisciplinary | F22: 27 | G22: 44805 | H22: 48 | I22: ['HKUST'] | J22: 344 | K22: 1 | L22: 0 | M22: 0 | N22: Sep | O22: 2022 | P22: Education
A23: 21 | B23: HKUST | C23: Development of HKUST(GZ) | D23: =VLOOKUP(YouTube_University_Data_Final[[#This Row],[Title]],[1]!YouTube_University_Data_Final[[Title]:[Title_language]],2,FALSE) -> English | E23: [ Witness the Birth of HKUST(GZ) from Concept to Reality ] Three years after the ground-breaking ceremony on 26 September 2019, an empty plot of land in Nansha, Guangzhou has morphed into a state-of-the-art campus which is now HKUST(GZ). Check out this miraculous journey and enjoy some stunning views of HKUST(GZ). #HKUSTevent #Architecture #NewBeginning #Celebration #Education #CrossCampus #HigherEducation #University #GBA #GreaterBayArea #Interdisciplinary #CrossDisciplinary | F23: 27 | G23: 44805 | H23: 403 | I23: ['HKUST'] | J23: 411 | K23: 7 | L23: 0 | M23: 0 | N23: Sep | O23: 2022 | P23: Education
A24: 22 | B24: HKUST | C24: HKUSTGZ aerial | D24: =VLOOKUP(YouTube_University_Data_Final[[#This Row],[Title]],[1]!YouTube_University_Data_Final[[Title]:[Title_language]],2,FALSE) -> English | F24: 27 | G24: 44805 | H24: 101 | I24: ['HKUST'] | J24: 478 | K24: 9 | L24: 0 | M24: 1 | N24: Sep | O24: 2022 | P24: Education
A25: 23 | B25: HKUST | C25: HKUST Welcome Back | D25: =VLOOKUP(YouTube_University_Data_Final[[#This Row],[Title]],[1]!YouTube_University_Data_Final[[Title]:[Title_language]],2,FALSE) -> English | E25: Are you ready to start a new year of adventures and fun? See you all at #HKUST soon! #BackToSchool #WelcomeBack #WelcomeHome #NewSchoolYear #helloagain | F25: 27 | G25: 44803 | H25: 2 | I25: ['HKUST'] | J25: 338 | K25: 6 | L25: 0 | M25: 0 | N25: Aug | O25: 2022 | P25: Education
A26: 24 | B26: HKUST | C26: APRU Metagame Conference 2022 | D26: =VLOOKUP(YouTube_University_Data_Final[[#This Row],[Title]],[1]!YouTube_University_Data_Final[[Title]:[Title_language]],2,FALSE) -> English | E26: The APRU Metagame Conference 2022 incorporates the full ecosystem of Esports. This metaverse experience includes high-level policy discussions, expert insights, next-generation learning, student competitions, and gaming. The conference will examine the ways that an international network of esports leaders can further its scope within universities including edutainment, collegiate esports, and gamification of social well-being. The conference is also the spotlight event of Cyberport Hong Kong’s Digital Entertainment Leadership Forum (DELF) and is hosted in partnership with The Hong Kong University of Science and Technology (HKUST). | F26: 27 | G26: 44800 | H26: 14111 | I26: ['HKUST'] | J26: 244 | K26: 12 | L26: 0 | M26: 1 | N26: Aug | O26: 2022 | P26: Education
A27: 25 | B27: HKUST | C27: HKUST(GZ) video - Traditional Chinese Version | D27: =VLOOKUP(YouTube_University_Data_Final[[#This Row],[Title]],[1]!YouTube_University_Data_Final[[Title]:[Title_language]],2,FALSE) -> English | F27: 27 | G27: 44799 | H27: 503 | I27: ['HKUST'] | J27: 198 | K27: 1 | L27: 0 | M27: 0 | N27: Aug | O27: 2022 | P27: Education
A28: 26 | B28: HKUST | C28: HKUST(GZ) video - Simplified Chinese Version | D28: =VLOOKUP(YouTube_University_Data_Final[[#This Row],[Title]],[1]!YouTube_University_Data_Final[[Title]:[Title_language]],2,FALSE) -> English | F28: 27 | G28: 44799 | H28: 16 | I28: ['HKUST'] | J28: 66 | K28: 0 | L28: 0 | M28: 0 | N28: Aug | O28: 2022 | P28: Education
A29: 27 | B29: HKUST | C29: JUPAS選科 | 學生Katie分享 | 科大工學院 | D29: =VLOOKUP(YouTube_University_Data_Final[[#This Row],[Title]],[1]!YouTube_University_Data_Final[[Title]:[Title_language]],2,FALSE) -> Chinese | E29: 【有得選一定選神科？】🛣🏫站在JUPAS選科的十字路口，現科大工學院學生Katie在當年交出了一份不一樣的答案。👷🏻‍♀️✨ 📍瀏覽工學院本科入學指南：bit.ly/3PvIeC4 [Choose the best or what’s best for you?] 🛣🏫When deciding which university program to enter during JUPAS admission two years ago, current HKUST Engineering student Katie had chosen to embark on a different journey.👷🏻‍♀️✨ 📍Learn more about SENG’s undergraduate admission: bit.ly/3PvIeC4 Source: HKUST Engineering #科大 #科大工程 #大學聯招 #本科課程 #文憑試 #科大見 #選科 #hkust #hkustengineering #JUPAS #JS5200 #JS5211 #JS5282 #undergraduate #admission #dse2022 #joinus #universityprogram | F29: 27 | G29: 44783 | H29: 130 | I29: ['HKUST'] | J29: 570 | K29: 3 | L29: 0 | M29: 0 | N29: Aug | O29: 2022 | P29: Education
A30: 28 | B30: HKUST | C30: HKUST Engineering Alumni Summer Mixer 2022 | D30: =VLOOKUP(YouTube_University_Data_Final[[#This Row],[Title]],[1]!YouTube_University_Data_Final[[Title]:[Title_language]],2,FALSE) -> English | E30: [🥂Summer Mixer 2022✨] #ThrowBackTo some of our favorite moments from the reunion last month, we really can’t get enough of those happy faces!🥳🙌🏻 📸Can you spot yourself in the video? Source: HKUST Engineering #hkust #hkustengineering #hkustfaculty #hkustalumni #hkuststudent #hkustnetwork #hkustevent #SENGSummerMixer #HKSTP #ACCESS #HKCRC #networking #artificialintelligence #robotics #tbt | F30: 27 | G30: 44783 | H30: 97 | I30: ['HKUST'] | J30: 198 | K30: 0 | L30: 0 | M30: 0 | N30: Aug | O30: 2022 | P30: Education
A31: 29 | B31: HKUST | C31: 科大工學院 十年活動回顧 | HKUST SENG 10 Years In Review | D31: =VLOOKUP(YouTube_University_Data_Final[[#This Row],[Title]],[1]!YouTube_University_Data_Final[[Title]:[Title_language]],2,FALSE) -> Bilingual | E31: Moments pass but memories remain. In the past ten years, we had organized events of all scales, connected with countless people affiliated with the Engineering School, and created plenty of precious memories together. 與歲月對望，唯有回憶中的你我恆久不變。十年間，我們透過舉辦形形色色的活動，凝聚了無數張代表工學院的面孔，創造了屬於工學院的獨特回憶。 Source: HKUST Engineering #hkust #hkustengineering #hkustfaculty #hkustalumni #hkuststudent #hkustnetwork #hkustevent #networking #eventrecap #reunion #video #科大 #科大工程 #科大教授 #科大學生 #科大校友 #科大舊生 #科大網絡 #科大活動 #活動回顧 #短片 | F31: 27 | G31: 44783 | H31: 561 | I31: ['HKUST'] | J31: 60 | K31: 0 | L31: 0 | M31: 0 | N31: Aug | O31: 2022 | P31: Education
A32: 30 | B32: HKUST | C32: 𝗗𝗲𝗳𝗹𝗲𝗰𝘁𝗶𝗻𝗴 𝗗𝗶𝗳𝗳𝗶𝗰𝘂𝗹𝘁 𝗤𝘂𝗲𝘀𝘁𝗶𝗼𝗻𝘀 𝗶𝗻 𝗜𝗻𝘁𝗲𝗿𝘃𝗶𝗲𝘄𝘀 | D32: =VLOOKUP(YouTube_University_Data_Final[[#This Row],[Title]],[1]!YouTube_University_Data_Final[[Title]:[Title_language]],2,FALSE) -> English | E32: Why does deflection work so well? And how to defend against deflection, if the roles are reversed? Read his full study at: https://bit.ly/3JmmvKF | F32: 27 | G32: 44775 | H32: 154 | I32: ['HKUST'] | J32: 88 | K32: 2 | L32: 0 | M32: 0 | N32: Aug | O32: 2022 | P32: Education
A33: 31 | B33: HKUST | C33: Multi-functional autonomous vehicle at HKUST | D33: =VLOOKUP(YouTube_University_Data_Final[[#This Row],[Title]],[1]!YouTube_University_Data_Final[[Title]:[Title_language]],2,FALSE) -> English | E33: Multi-functional autonomous vehicle brings a new normal to HKUST. If you're interested in licensing the technologies, please contact us at ttcac@ust.hk. #HKUST_TTC #robotics | F33: 27 | G33: 44769 | H33: 30 | I33: ['HKUST'] | J33: 217 | K33: 3 | L33: 0 | M33: 0 | N33: Jul | O33: 2022 | P33: Education
A34: 32 | B34: HKUST | C34: "Ultrasonic Drug Delivery System" by HKUST | D34: =VLOOKUP(YouTube_University_Data_Final[[#This Row],[Title]],[1]!YouTube_University_Data_Final[[Title]:[Title_language]],2,FALSE) -> English | E34: Non-invasive Ultrasound Ocular Drug Delivery Technology If you're interested, please contact us at ttcac@ust.hk. #HKUST_TTC #biotechnology #medtech | F34: 27 | G34: 44769 | H34: 199 | I34: ['HKUST'] | J34: 129 | K34: 3 | L34: 0 | M34: 0 | N34: Jul | O34: 2022 | P34: Education
A35: 33 | B35: HKUST | C35: "StayHomeSafe" App by HKUST | D35: =VLOOKUP(YouTube_University_Data_Final[[#This Row],[Title]],[1]!YouTube_University_Data_Final[[Title]:[Title_language]],2,FALSE) -> English | E35: Geo-Fencing technology in StayHomeSafe apps to faciliate government in coronavirus quarantine tracking If you're interested in licensing the technologies, please contact us at ttcac@ust.hk. #HKUST_TTC #ar #robotics #geofencing | F35: 27 | G35: 44769 | H35: 179 | I35: ['HKUST'] | J35: 154 | K35: 4 | L35: 0 | M35: 0 | N35: Jul | O35: 2022 | P35: Education
A36: 34 | B36: HKUST | C36: “Electronic Nose” by HKUST | D36: =VLOOKUP(YouTube_University_Data_Final[[#This Row],[Title]],[1]!YouTube_University_Data_Final[[Title]:[Title_language]],2,FALSE) -> English | E36: A robust low power nanotube sensor array with high sensitivity If you're interested in licensing the technologies, please contact us at ttcac@ust.hk. #HKUST_TTC #microelectronics #mox_sensors | F36: 27 | G36: 44769 | H36: 158 | I36: ['HKUST'] | J36: 64 | K36: 1 | L36: 0 | M36: 0 | N36: Jul | O36: 2022 | P36: Education
A37: 35 | B37: HKUST | C37: "New Smart Antimicrobial Coating" Technology by HKUST | D37: =VLOOKUP(YouTube_University_Data_Final[[#This Row],[Title]],[1]!YouTube_University_Data_Final[[Title]:[Title_language]],2,FALSE) -> English | E37: New Smart Anti-Microbial Coating in the Fight Against COVID-19 If you're interested in licensing the technologies, please contact us at ttcac@ust.hk. #HKUST_TTC #sustainability #materials | F37: 27 | G37: 44769 | H37: 157 | I37: ['HKUST'] | J37: 69 | K37: 0 | L37: 0 | M37: 0 | N37: Jul | O37: 2022 | P37: Education
A38: 36 | B38: HKUST | C38: HKUST's New Products to Prevent Alzheimer's Disease | D38: =VLOOKUP(YouTube_University_Data_Final[[#This Row],[Title]],[1]!YouTube_University_Data_Final[[Title]:[Title_language]],2,FALSE) -> English | E38: Strengthen Your Brain with Chinese Herbs to Prevent Alzheimer's If you're interested, please contact us at ttcac@ust.hk. #HKUST_TTC #biotechnology | F38: 27 | G38: 44769 | H38: 186 | I38: ['HKUST'] | J38: 85 | K38: 1 | L38: 0 | M38: 0 | N38: Jul | O38: 2022 | P38: Education
A39: 37 | B39: HKUST | C39: Conversation with the National Winter Olympic Team 北京冬奧精神雲分享 | D39: =VLOOKUP(YouTube_University_Data_Final[[#This Row],[Title]],[1]!YouTube_University_Data_Final[[Title]:[Title_language]],2,FALSE) -> Bilingual | E39: HKUST was excited to hold a live sharing session on 19 July 2022 with a team of National and Hong Kong Olympians, staff, and volunteers who have participated in the Olympic Winter Games Beijing 2022. Sharing at the “Conversation with National Team Winter Olympians” were Olympic gold medalists snowboarder SU Yiming; wheelchair curler YAB Zhuo; figure skater SUI Wenjing; as well as Sidney CHU, Beijing Winter Olympic Hong Kong, China team’s flag-bearer and short-track speedskater; WU Xiaonan, Director of the Operations Team of the National Speed Skating Oval; ZHAO Hongbo, Chief Coach of China’s National Figure Skating Team and LI Jiaxin, Beijing Winter Olympics volunteer. The interactive session saw over 400 members from the HKUST community be inspired by the personal stories and insights shared by the speakers, who encouraged everyone to adopt the spirit of the Beijing Winter Olympics and pursue their goals with passion, resilience, and dedication. Officiating at the event were Mr. Kevin YEUNG Yun-Hung, Secretary for Culture, Sports and Tourism; Mr. ZHANG Guoyi, Deputy Director of Department of Publicity, Culture and Sports Affairs of the LOCPG; Mr. Andrew LIAO Cheung-Sing, HKUST Council Chairman; Mr. Philip CHEN, Chairman of The Hong Kong Jockey Club; Mr. Kenneth FOK Kai-Kong, Vice President of the Sports Federation & Olympic Committee of Hong Kong and Prof. Wei SHYY, HKUST President. Supported by The Hong Kong Jockey Club, the sharing session was jointly hosted by the Beijing Organizing Committee for the 2022 Olympic and Paralympic Winter Games, General Administration of Sport of China, China Disabled Persons Federation, the Liaison Office of the Central People’s Government in the HKSAR (LOCPG) and the HKSAR Government. Learn more: https://bit.ly/3yLIbLm | F39: 27 | G39: 44762 | H39: 7108 | I39: ['HKUST'] | J39: 78 | K39: 0 | L39: 0 | M39: 0 | N39: Jul | O39: 2022 | P39: Education
A40: 38 | B40: HKUST | C40: HKUST(GZ) the Red Bird Sundial installation | D40: =VLOOKUP(YouTube_University_Data_Final[[#This Row],[Title]],[1]!YouTube_University_Data_Final[[Title]:[Title_language]],2,FALSE) -> English | F40: 27 | G40: 44754 | H40: 32 | I40: ['HKUST'] | J40: 521 | K40: 7 | L40: 0 | M40: 0 | N40: Jul | O40: 2022 | P40: Education
...

Sheet Radar Source
A1: Radar Category | B1: The Hong Kong Polytechnic University | C1: HKUST | D1: CityUHongKong | E1: CUHK Channel | F1: The University of Hong Kong | G1: MIN | H1: MAX | I1: RANGE | J1: AVG | K1: SD
A2: AVG. View | B2: =AVERAGEIFS(YouTube_University_Data_Final[Views],YouTube_University_Data_Final[Channel_name],'Radar Source'!B1,YouTube_University_Data_Final[Year],">2017") -> 7686.5455 | C2: =AVERAGEIFS(YouTube_University_Data_Final[Views],YouTube_University_Data_Final[Channel_name],'Radar Source'!C1,YouTube_University_Data_Final[Year],">2017") -> 1387.7542 | D2: =AVERAGEIFS(YouTube_University_Data_Final[Views],YouTube_University_Data_Final[Channel_name],'Radar Source'!D1,YouTube_University_Data_Final[Year],">2017") -> 22316.287 | E2: =AVERAGEIFS(YouTube_University_Data_Final[Views],YouTube_University_Data_Final[Channel_name],'Radar Source'!E1,YouTube_University_Data_Final[Year],">2017") -> 4212.5573 | F2: =AVERAGEIFS(YouTube_University_Data_Final[Views],YouTube_University_Data_Final[Channel_name],'Radar Source'!F1,YouTube_University_Data_Final[Year],">2017") -> 3534.0899 | G2: =MIN($B2:$F2) -> 1387.7542 | H2: =MAX($B2:$F2) -> 22316.287 | I2: =H2-G2 -> 20928.532 | J2: =AVERAGE($B2:$F2) -> 7827.4467 | K2: =_xlfn.STDEV.S($B2:$F2) -> 8410.0582
A3: AVG. Likes | B3: =AVERAGEIFS(YouTube_University_Data_Final[Likes],YouTube_University_Data_Final[Channel_name],'Radar Source'!B1,YouTube_University_Data_Final[Year],">2017") -> 19.329545 | C3: =AVERAGEIFS(YouTube_University_Data_Final[Likes],YouTube_University_Data_Final[Channel_name],'Radar Source'!C1,YouTube_University_Data_Final[Year],">2017") -> 15.089385 | D3: =AVERAGEIFS(YouTube_University_Data_Final[Likes],YouTube_University_Data_Final[Channel_name],'Radar Source'!D1,YouTube_University_Data_Final[Year],">2017") -> 12.22293 | E3: =AVERAGEIFS(YouTube_University_Data_Final[Likes],YouTube_University_Data_Final[Channel_name],'Radar Source'!E1,YouTube_University_Data_Final[Year],">2017") -> 40.12253 | F3: =AVERAGEIFS(YouTube_University_Data_Final[Likes],YouTube_University_Data_Final[Channel_name],'Radar Source'!F1,YouTube_University_Data_Final[Year],">2017") -> 16.501071 | G3: =MIN($B3:$F3) -> 12.22293 | H3: =MAX($B3:$F3) -> 40.12253 | I3: =H3-G3 -> 27.8996 | J3: =AVERAGE($B3:$F3) -> 20.653092 | K3: =_xlfn.STDEV.S($B3:$F3) -> 11.181151
A4: AVG. Likes Per View | B4: =B3/B2 -> 0.0025147247 | C4: =C3/C2 -> 0.010873241 | D4: =D3/D2 -> 0.00054771343 | E4: =E3/E2 -> 0.0095245065 | F4: =F3/F2 -> 0.0046691145 | G4: =MIN($B4:$F4) -> 0.00054771343 | H4: =MAX($B4:$F4) -> 0.010873241 | I4: =H4-G4 -> 0.010325527 | J4: =AVERAGE($B4:$F4) -> 0.00562586 | K4: =_xlfn.STDEV.S($B4:$F4) -> 0.0044473742
A5: AVG. No. of Videos Per Year | B5: =COUNTIFS(YouTube_University_Data_Final[Channel_name],B1,YouTube_University_Data_Final[Year],">2017")/5 -> 52.8 | C5: =COUNTIFS(YouTube_University_Data_Final[Channel_name],C1,YouTube_University_Data_Final[Year],">2017")/5 -> 35.8 | D5: =COUNTIFS(YouTube_University_Data_Final[Channel_name],D1,YouTube_University_Data_Final[Year],">2017")/5 -> 31.4 | E5: =COUNTIFS(YouTube_University_Data_Final[Channel_name],E1,YouTube_University_Data_Final[Year],">2017")/5 -> 50.6 | F5: =COUNTIFS(YouTube_University_Data_Final[Channel_name],F1,YouTube_University_Data_Final[Year],">2017")/5 -> 93.4 | G5: =MIN($B5:$F5) -> 31.4 | H5: =MAX($B5:$F5) -> 93.4 | I5: =H5-G5 -> 62 | J5: =AVERAGE($B5:$F5) -> 52.8 | K5: =_xlfn.STDEV.S($B5:$F5) -> 24.495714
A6: AVG. Duration Per Video | B6: =SUMIFS(YouTube_University_Data_Final[Duration],YouTube_University_Data_Final[Channel_name],B1,YouTube_University_Data_Final[Year],">2017")/COUNTIFS(YouTube_University_Data_Final[Channel_name],B1,YouTube_University_Data_Final[Year],">2017") -> 801.94697 | C6: =SUMIFS(YouTube_University_Data_Final[Duration],YouTube_University_Data_Final[Channel_name],C1,YouTube_University_Data_Final[Year],">2017")/COUNTIFS(YouTube_University_Data_Final[Channel_name],C1,YouTube_University_Data_Final[Year],">2017") -> 409.67039 | D6: =SUMIFS(YouTube_University_Data_Final[Duration],YouTube_University_Data_Final[Channel_name],D1,YouTube_University_Data_Final[Year],">2017")/COUNTIFS(YouTube_University_Data_Final[Channel_name],D1,YouTube_University_Data_Final[Year],">2017") -> 351.19745 | E6: =SUMIFS(YouTube_University_Data_Final[Duration],YouTube_University_Data_Final[Channel_name],E1,YouTube_University_Data_Final[Year],">2017")/COUNTIFS(YouTube_University_Data_Final[Channel_name],E1,YouTube_University_Data_Final[Year],">2017") -> 671.05534 | F6: =SUMIFS(YouTube_University_Data_Final[Duration],YouTube_University_Data_Final[Channel_name],F1,YouTube_University_Data_Final[Year],">2017")/COUNTIFS(YouTube_University_Data_Final[Channel_name],F1,YouTube_University_Data_Final[Year],">2017") -> 1051.1606 | G6: =MIN($B6:$F6) -> 351.19745 | H6: =MAX($B6:$F6) -> 1051.1606 | I6: =H6-G6 -> 699.96315 | J6: =AVERAGE($B6:$F6) -> 657.00615 | K6: =_xlfn.STDEV.S($B6:$F6) -> 287.7746
A7: AVG. Percentage of Hot Videos | B7: =COUNTIFS(YouTube_University_Data_Final[Views],">5000",YouTube_University_Data_Final[Channel_name],'Radar Source'!B1,YouTube_University_Data_Final[Year],">2017")/5/B5 -> 0.15909091 | C7: =COUNTIFS(YouTube_University_Data_Final[Views],">5000",YouTube_University_Data_Final[Channel_name],'Radar Source'!C1,YouTube_University_Data_Final[Year],">2017")/5/C5 -> 0.027932961 | D7: =COUNTIFS(YouTube_University_Data_Final[Views],">5000",YouTube_University_Data_Final[Channel_name],'Radar Source'!D1,YouTube_University_Data_Final[Year],">2017")/5/D5 -> 0.41401274 | E7: =COUNTIFS(YouTube_University_Data_Final[Views],">5000",YouTube_University_Data_Final[Channel_name],'Radar Source'!E1,YouTube_University_Data_Final[Year],">2017")/5/E5 -> 0.079051383 | F7: =COUNTIFS(YouTube_University_Data_Final[Views],">5000",YouTube_University_Data_Final[Channel_name],'Radar Source'!F1,YouTube_University_Data_Final[Year],">2017")/5/F5 -> 0.094218415 | G7: =MIN($B7:$F7) -> 0.027932961 | H7: =MAX($B7:$F7) -> 0.41401274 | I7: =H7-G7 -> 0.38607978 | J7: =AVERAGE($B7:$F7) -> 0.15486128 | K7: =_xlfn.STDEV.S($B7:$F7) -> 0.15224394

Sheet Radar Result
A1: Radar Category | B1: The Hong Kong Polytechnic University | C1: HKUST | D1: CityUHongKong | E1: CUHK Channel | F1: The University of Hong Kong
A2: AVG. View | B2: =RANK('Radar Source'!B2,'Radar Source'!$B2:$F2,1)*2 -> 8 | C2: =RANK('Radar Source'!C2,'Radar Source'!$B2:$F2,1)*2 -> 2 | D2: =RANK('Radar Source'!D2,'Radar Source'!$B2:$F2,1)*2 -> 10 | E2: =RANK('Radar Source'!E2,'Radar Source'!$B2:$F2,1)*2 -> 6 | F2: =RANK('Radar Source'!F2,'Radar Source'!$B2:$F2,1)*2 -> 4
A3: AVG. Likes | B3: =RANK('Radar Source'!B3,'Radar Source'!$B3:$F3,1)*2 -> 8 | C3: =RANK('Radar Source'!C3,'Radar Source'!$B3:$F3,1)*2 -> 4 | D3: =RANK('Radar Source'!D3,'Radar Source'!$B3:$F3,1)*2 -> 2 | E3: =RANK('Radar Source'!E3,'Radar Source'!$B3:$F3,1)*2 -> 10 | F3: =RANK('Radar Source'!F3,'Radar Source'!$B3:$F3,1)*2 -> 6
A4: AVG. Likes Per View | B4: =RANK('Radar Source'!B4,'Radar Source'!$B4:$F4,1)*2 -> 4 | C4: =RANK('Radar Source'!C4,'Radar Source'!$B4:$F4,1)*2 -> 10 | D4: =RANK('Radar Source'!D4,'Radar Source'!$B4:$F4,1)*2 -> 2 | E4: =RANK('Radar Source'!E4,'Radar Source'!$B4:$F4,1)*2 -> 8 | F4: =RANK('Radar Source'!F4,'Radar Source'!$B4:$F4,1)*2 -> 6
A5: AVG. No. of Videos Per Year | B5: =RANK('Radar Source'!B5,'Radar Source'!$B5:$F5,1)*2 -> 8 | C5: =RANK('Radar Source'!C5,'Radar Source'!$B5:$F5,1)*2 -> 4 | D5: =RANK('Radar Source'!D5,'Radar Source'!$B5:$F5,1)*2 -> 2 | E5: =RANK('Radar Source'!E5,'Radar Source'!$B5:$F5,1)*2 -> 6 | F5: =RANK('Radar Source'!F5,'Radar Source'!$B5:$F5,1)*2 -> 10
A6: AVG. Duration Per Video | B6: =RANK('Radar Source'!B6,'Radar Source'!$B6:$F6,1)*2 -> 8 | C6: =RANK('Radar Source'!C6,'Radar Source'!$B6:$F6,1)*2 -> 4 | D6: =RANK('Radar Source'!D6,'Radar Source'!$B6:$F6,1)*2 -> 2 | E6: =RANK('Radar Source'!E6,'Radar Source'!$B6:$F6,1)*2 -> 6 | F6: =RANK('Radar Source'!F6,'Radar Source'!$B6:$F6,1)*2 -> 10
A7: AVG. Percentage of Hot Videos | B7: =RANK('Radar Source'!B7,'Radar Source'!$B7:$F7,1)*2 -> 8 | C7: =RANK('Radar Source'!C7,'Radar Source'!$B7:$F7,1)*2 -> 2 | D7: =RANK('Radar Source'!D7,'Radar Source'!$B7:$F7,1)*2 -> 10 | E7: =RANK('Radar Source'!E7,'Radar Source'!$B7:$F7,1)*2 -> 4 | F7: =RANK('Radar Source'!F7,'Radar Source'!$B7:$F7,1)*2 -> 6

Sheet Original Channel Name
A1: The Hong Kong Polytechnic University
A2: HKUST
A3: CityUHongKong
A4: CUHK Channel
A5: The University of Hong Kong
